Workbook

Sheet حسب المشرف والنقطة
A2: توزيع الموظفين حسب المشرف ونقطة الدوام
A3: مشروع الغذاء العالمي WFP — سبتمبر 2026
A4: إجمالي سجلات الموظفين | D4: المشرفون الميدانيون | G4: نقاط الدوام الفريدة | J4: توجيهات النقاط حسب المشرف
A5: =COUNTA('قاعدة البيانات'!C4:C171) -> 145 | D5: 4 | G5: 28 | J5: 33
A7: ملخص توزيع الفرق | K7: طريقة العرض يظهر كل مشرف في قسم مستقل، وتحته نقاط الدوام بالترتيب، ثم الجدول الكامل لموظفي كل نقطة. تبقى ورقة قاعدة البيانات المصدر الأساسي للبحث والفلترة.
A8: المشرف | B8: الموظفون | C8: النقاط | D8: وقائي | E8: علاجي | F8: أمن | G8: موظف/ة | H8: متطوع/ة | I8: النطاقات | J8: وصف وظيفي
A9: أمل عوض | B9: 4 | C9: 0 | D9: 0 | E9: 0 | F9: 0 | G9: 0 | H9: 0 | I9: إدارة عليا (كامل المشروع) | J9: أعلى سلطة إدارية في المشروع - تدير المشرفين الميدانيين
A10: أشرف الصليبي | B10: 35 | C10: 8 | D10: 35 | E10: 0 | F10: 8 | G10: 19 | H10: 8 | I10: الوسطى، خانيونس | J10: مشرف/ة ميداني على 8 نقاط في برنامج BSFP + Cash
A11: براء الاسطل | B11: 40 | C11: 8 | D11: 39 | E11: 1 | F11: 8 | G11: 23 | H11: 9 | I11: الوسطى، غزة | J11: مشرف/ة ميداني على 8 نقاط في برنامج BSFP + Cash
A12: هادي الأحول | B12: 28 | C12: 9 | D12: 9 | E12: 19 | F12: 8 | G12: 12 | H12: 8 | I12: الوسطى، خانيونس، غزة | J12: مشرف/ة ميداني على 2 نقطة في برنامج BSFP + مشرف على 8 نقاط في برنامج TSFP
A13: ياسمين النجيلي | B13: 37 | C13: 8 | D13: 37 | E13: 0 | F13: 7 | G13: 22 | H13: 8 | I13: خانيونس | J13: مشرف/ة ميداني على 8 نقاط في برنامج BSFP + Cash
A16: التفاصيل الكاملة حسب المشرف والنقطة
A18: 01 — إداري
A19: الموظفون: 4 | D19: النقاط: 1 | G19: الأقسام: إداري: 4 | J19: المناطق: إداري
A21: نقطة 01 | C21: إداري | G21: الموظفون: 4 | I21: المنطقة: إداري | K21: النطاق: إداري
A22: # | B22: رقم الهوية | C22: الاسم الرباعي | D22: رقم الجوال | E22: القسم | F22: الفئة الوظيفية | G22: المشرف المباشر | H22: مشرف النقطة | I22: نقطة الدوام | J22: النطاق الجغرافي | K22: منطقة النقطة | L22: عدد موظفي النقطة | M22: حالة البيانات
A23: ='قاعدة البيانات'!A4 -> 1 | B23: ='قاعدة البيانات'!B4 -> 949827901 | C23: ='قاعدة البيانات'!C4 -> أمل سمير اسماعيل عوض | D23: ='قاعدة البيانات'!D4 -> 599481714 | E23: ='قاعدة البيانات'!E4 -> إدارة عليا | F23: ='قاعدة البيانات'!F4 -> منسق/ة | G23: ='قاعدة البيانات'!G4 -> مديرة المشاريع | H23: ='قاعدة البيانات'!H4 -> إداري | ... M23: ='قاعدة البيانات'!M4 -> سليم
A24: ='قاعدة البيانات'!A5 -> 2 | B24: ='قاعدة البيانات'!B5 -> 402938682 | C24: ='قاعدة البيانات'!C5 -> أشرف أسامة دياب الصليبي | D24: ='قاعدة البيانات'!D5 -> 598466903 | E24: ='قاعدة البيانات'!E5 -> إداري ميداني | F24: ='قاعدة البيانات'!F5 -> مشرف/ة | G24: ='قاعدة البيانات'!G5 -> إداري | H24: ='قاعدة البيانات'!H5 -> إداري | ... M24: ='قاعدة البيانات'!M5 -> سليم
A25: ='قاعدة البيانات'!A6 -> 3 | B25: ='قاعدة البيانات'!B6 -> 403703689 | C25: ='قاعدة البيانات'!C6 -> براء محمد قاسم الاسطل | D25: ='قاعدة البيانات'!D6 -> 0592238075 | E25: ='قاعدة البيانات'!E6 -> إداري ميداني | F25: ='قاعدة البيانات'!F6 -> مشرف/ة | G25: ='قاعدة البيانات'!G6 -> إداري | H25: ='قاعدة البيانات'!H6 -> إداري | ... M25: ='قاعدة البيانات'!M6 -> سليم
A26: ='قاعدة البيانات'!A7 -> 4 | B26: ='قاعدة البيانات'!B7 -> 411100480 | C26: ='قاعدة البيانات'!C7 -> هادي عيسى سعيد الأحول | D26: ='قاعدة البيانات'!D7 -> 597828787 | E26: ='قاعدة البيانات'!E7 -> إداري ميداني | F26: ='قاعدة البيانات'!F7 -> مشرف/ة | G26: ='قاعدة البيانات'!G7 -> إداري | H26: ='قاعدة البيانات'!H7 -> إداري | ... M26: ='قاعدة البيانات'!M7 -> سليم
A27: ='قاعدة البيانات'!A8 -> 5 | B27: ='قاعدة البيانات'!B8 -> 402963664 | C27: ='قاعدة البيانات'!C8 -> ياسمين مجدي محمد النجيلي | D27: ='قاعدة البيانات'!D8 -> 597233284 | E27: ='قاعدة البيانات'!E8 -> إداري ميداني | F27: ='قاعدة البيانات'!F8 -> مشرف/ة | G27: ='قاعدة البيانات'!G8 -> إداري | H27: ='قاعدة البيانات'!H8 -> إداري | ... M27: ='قاعدة البيانات'!M8 -> سليم
A30: 02 — أشرف الصليبي
A31: الموظفون: 35 | D31: النقاط: 8 | G31: الأقسام: وقائي: 35 | J31: المناطق: النصيرات، دير البلح، القرارة، خانيونس
A33: نقطة 01 | C33: البرامج النسائية - النصيرات | G33: الموظفون: 5 | I33: المنطقة: النصيرات | K33: النطاق: الوسطى
A34: # | B34: رقم الهوية | C34: الاسم الرباعي | D34: رقم الجوال | E34: القسم | F34: الفئة الوظيفية | G34: المشرف المباشر | H34: مشرف النقطة | I34: نقطة الدوام | J34: النطاق الجغرافي | K34: منطقة النقطة | L34: عدد موظفي النقطة | M34: حالة البيانات
A35: ='قاعدة البيانات'!A9 -> 6 | B35: ='قاعدة البيانات'!B9 -> 421220104 | C35: ='قاعدة البيانات'!C9 -> أحمد حرب علي الطويل | D35: ='قاعدة البيانات'!D9 -> 592507696 | E35: ='قاعدة البيانات'!E9 -> وقائي | F35: ='قاعدة البيانات'!F9 -> أمن | G35: ='قاعدة البيانات'!G9 -> أشرف الصليبي | H35: ='قاعدة البيانات'!H9 -> أشرف الصليبي | ... M35: ='قاعدة البيانات'!M9 -> سليم
A36: ='قاعدة البيانات'!A10 -> 7 | B36: ='قاعدة البيانات'!B10 -> 407075688 | C36: ='قاعدة البيانات'!C10 -> لانا صلاح قدسي الوحيدي | D36: ='قاعدة البيانات'!D10 -> 592665365 | E36: ='قاعدة البيانات'!E10 -> وقائي | F36: ='قاعدة البيانات'!F10 -> موظف/ة | G36: ='قاعدة البيانات'!G10 -> أشرف الصليبي | H36: ='قاعدة البيانات'!H10 -> أشرف الصليبي | ... M36: ='قاعدة البيانات'!M10 -> سليم
A37: ='قاعدة البيانات'!A11 -> 8 | B37: ='قاعدة البيانات'!B11 -> 403019169 | C37: ='قاعدة البيانات'!C11 -> محمد سيد ابراهيم ابو شماله | D37: ='قاعدة البيانات'!D11 -> 597712731 | E37: ='قاعدة البيانات'!E11 -> وقائي | F37: ='قاعدة البيانات'!F11 -> موظف/ة | G37: ='قاعدة البيانات'!G11 -> أشرف الصليبي | H37: ='قاعدة البيانات'!H11 -> أشرف الصليبي | ... M37: ='قاعدة البيانات'!M11 -> سليم
A38: ='قاعدة البيانات'!A12 -> 9 | B38: ='قاعدة البيانات'!B12 -> 400179628 | C38: ='قاعدة البيانات'!C12 -> ياسر جهاد يونس أبو خاطر | D38: ='قاعدة البيانات'!D12 -> 595176949 | E38: ='قاعدة البيانات'!E12 -> وقائي | F38: ='قاعدة البيانات'!F12 -> موظف/ة | G38: ='قاعدة البيانات'!G12 -> أشرف الصليبي | H38: ='قاعدة البيانات'!H12 -> أشرف الصليبي | ... M38: ='قاعدة البيانات'!M12 -> سليم
A39: ='قاعدة البيانات'!A13 -> 10 | B39: ='قاعدة البيانات'!B13 -> 420530016 | C39: ='قاعدة البيانات'!C13 -> رهف أحمد محمد الصالحي | D39: ='قاعدة البيانات'!D13 -> 567160712 | E39: ='قاعدة البيانات'!E13 -> وقائي | F39: ='قاعدة البيانات'!F13 -> متطوع/ة | G39: ='قاعدة البيانات'!G13 -> أشرف الصليبي | H39: ='قاعدة البيانات'!H13 -> أشرف الصليبي | ... M39: ='قاعدة البيانات'!M13 -> سليم
A41: نقطة 02 | C41: الحكر | G41: الموظفون: 4 | I41: المنطقة: دير البلح | K41: النطاق: الوسطى
A42: # | B42: رقم الهوية | C42: الاسم الرباعي | D42: رقم الجوال | E42: القسم | F42: الفئة الوظيفية | G42: المشرف المباشر | H42: مشرف النقطة | I42: نقطة الدوام | J42: النطاق الجغرافي | K42: منطقة النقطة | L42: عدد موظفي النقطة | M42: حالة البيانات
A43: ='قاعدة البيانات'!A14 -> 11 | B43: ='قاعدة البيانات'!B14 -> 403688468 | C43: ='قاعدة البيانات'!C14 -> احمد سامي سلامه العطار | D43: ='قاعدة البيانات'!D14 -> 592087997 | E43: ='قاعدة البيانات'!E14 -> وقائي | F43: ='قاعدة البيانات'!F14 -> متطوع/ة | G43: ='قاعدة البيانات'!G14 -> أشرف الصليبي | H43: ='قاعدة البيانات'!H14 -> أشرف الصليبي | ... M43: ='قاعدة البيانات'!M14 -> سليم
A44: ='قاعدة البيانات'!A15 -> 12 | B44: ='قاعدة البيانات'!B15 -> 407685163 | C44: ='قاعدة البيانات'!C15 -> اسلام سامي سلامة العطار | D44: ='قاعدة البيانات'!D15 -> 595782889 | E44: ='قاعدة البيانات'!E15 -> وقائي | F44: ='قاعدة البيانات'!F15 -> أمن | G44: ='قاعدة البيانات'!G15 -> أشرف الصليبي | H44: ='قاعدة البيانات'!H15 -> أشرف الصليبي | ... M44: ='قاعدة البيانات'!M15 -> سليم
A45: ='قاعدة البيانات'!A16 -> 13 | B45: ='قاعدة البيانات'!B16 -> 404143521 | C45: ='قاعدة البيانات'!C16 -> فاطمة بسام علي أبو بشير | D45: ='قاعدة البيانات'!D16 -> 567092181 | E45: ='قاعدة البيانات'!E16 -> وقائي | F45: ='قاعدة البيانات'!F16 -> موظف/ة | G45: ='قاعدة البيانات'!G16 -> أشرف الصليبي | H45: ='قاعدة البيانات'!H16 -> أشرف الصليبي | ... M45: ='قاعدة البيانات'!M16 -> سليم
A46: ='قاعدة البيانات'!A17 -> 14 | B46: ='قاعدة البيانات'!B17 -> 407040807 | C46: ='قاعدة البيانات'!C17 -> نهيل حمدالله عوض حمدالله | D46: ='قاعدة البيانات'!D17 -> 595341131 | E46: ='قاعدة البيانات'!E17 -> وقائي | F46: ='قاعدة البيانات'!F17 -> موظف/ة | G46: ='قاعدة البيانات'!G17 -> أشرف الصليبي | H46: ='قاعدة البيانات'!H17 -> أشرف الصليبي | ... M46: ='قاعدة البيانات'!M17 -> سليم
A48: نقطة 03 | C48: الزهور | G48: الموظفون: 4 | I48: المنطقة: دير البلح | K48: النطاق: الوسطى
A49: # | B49: رقم الهوية | C49: الاسم الرباعي | D49: رقم الجوال | E49: القسم | F49: الفئة الوظيفية | G49: المشرف المباشر | H49: مشرف النقطة | I49: نقطة الدوام | J49: النطاق الجغرافي | K49: منطقة النقطة | L49: عدد موظفي النقطة | M49: حالة البيانات
A50: ='قاعدة البيانات'!A18 -> 15 | B50: ='قاعدة البيانات'!B18 -> 404535759 | C50: ='قاعدة البيانات'!C18 -> أمل محمد سليمان شاهين | D50: ='قاعدة البيانات'!D18 -> 592247341 | E50: ='قاعدة البيانات'!E18 -> وقائي | F50: ='قاعدة البيانات'!F18 -> موظف/ة | G50: ='قاعدة البيانات'!G18 -> أشرف الصليبي | H50: ='قاعدة البيانات'!H18 -> أشرف الصليبي | ... M50: ='قاعدة البيانات'!M18 -> سليم
A51: ='قاعدة البيانات'!A19 -> 16 | B51: ='قاعدة البيانات'!B19 -> 409757309 | C51: ='قاعدة البيانات'!C19 -> سليمان زياد خماش | D51: ='قاعدة البيانات'!D19 -> 595268256 | E51: ='قاعدة البيانات'!E19 -> وقائي | F51: ='قاعدة البيانات'!F19 -> أمن | G51: ='قاعدة البيانات'!G19 -> أشرف الصليبي | H51: ='قاعدة البيانات'!H19 -> أشرف الصليبي | ... M51: ='قاعدة البيانات'!M19 -> سليم
...

Sheet قاعدة البيانات
A1: قاعدة بيانات الموظفين الموحدة — مشروع الغذاء العالمي WFP
A2: استخدم أسهم الفلترة في رؤوس الأعمدة للبحث حسب المشرف، النقطة، المنطقة، القسم أو الفئة الوظيفية
A3: # | B3: رقم الهوية | C3: الاسم الرباعي | D3: رقم الجوال | E3: القسم | F3: الفئة الوظيفية | G3: المشرف المباشر | H3: مشرف النقطة | I3: نقطة الدوام | J3: النطاق الجغرافي | K3: منطقة النقطة | L3: عدد موظفي النقطة | M3: حالة البيانات
A4: 1 | B4: 949827901 | C4: أمل سمير اسماعيل عوض | D4: 599481714 | E4: إدارة عليا | F4: منسق/ة | G4: مديرة المشاريع | H4: إداري | I4: إداري | J4: إداري | K4: إداري | M4: سليم
A5: 2 | B5: 402938682 | C5: أشرف أسامة دياب الصليبي | D5: 598466903 | E5: إداري ميداني | F5: مشرف/ة | G5: إداري | H5: إداري | I5: إداري | J5: إداري | K5: إداري | L5: =COUNTIF($I$4:$I$148,I5) -> 5 | M5: سليم
A6: 3 | B6: 403703689 | C6: براء محمد قاسم الاسطل | D6: 0592238075 | E6: إداري ميداني | F6: مشرف/ة | G6: إداري | H6: إداري | I6: إداري | J6: إداري | K6: إداري | L6: =COUNTIF($I$4:$I$148,I6) -> 5 | M6: سليم
A7: 4 | B7: 411100480 | C7: هادي عيسى سعيد الأحول | D7: 597828787 | E7: إداري ميداني | F7: مشرف/ة | G7: إداري | H7: إداري | I7: إداري | J7: إداري | K7: إداري | L7: =COUNTIF($I$4:$I$148,I7) -> 5 | M7: سليم
A8: 5 | B8: 402963664 | C8: ياسمين مجدي محمد النجيلي | D8: 597233284 | E8: إداري ميداني | F8: مشرف/ة | G8: إداري | H8: إداري | I8: إداري | J8: إداري | K8: إداري | L8: =COUNTIF($I$4:$I$148,I8) -> 5 | M8: سليم
A9: 6 | B9: 421220104 | C9: أحمد حرب علي الطويل | D9: 592507696 | E9: وقائي | F9: أمن | G9: أشرف الصليبي | H9: أشرف الصليبي | I9: البرامج النسائية - النصيرات | J9: الوسطى | K9: النصيرات | L9: =COUNTIF($I$4:$I$148,I9) -> 8 | M9: سليم
A10: 7 | B10: 407075688 | C10: لانا صلاح قدسي الوحيدي | D10: 592665365 | E10: وقائي | F10: موظف/ة | G10: أشرف الصليبي | H10: أشرف الصليبي | I10: البرامج النسائية - النصيرات | J10: الوسطى | K10: النصيرات | L10: =COUNTIF($I$4:$I$148,I10) -> 8 | M10: سليم
A11: 8 | B11: 403019169 | C11: محمد سيد ابراهيم ابو شماله | D11: 597712731 | E11: وقائي | F11: موظف/ة | G11: أشرف الصليبي | H11: أشرف الصليبي | I11: البرامج النسائية - النصيرات | J11: الوسطى | K11: النصيرات | L11: =COUNTIF($I$4:$I$148,I11) -> 8 | M11: سليم
A12: 9 | B12: 400179628 | C12: ياسر جهاد يونس أبو خاطر | D12: 595176949 | E12: وقائي | F12: موظف/ة | G12: أشرف الصليبي | H12: أشرف الصليبي | I12: البرامج النسائية - النصيرات | J12: الوسطى | K12: النصيرات | L12: =COUNTIF($I$4:$I$148,I12) -> 8 | M12: سليم
A13: 10 | B13: 420530016 | C13: رهف أحمد محمد الصالحي | D13: 567160712 | E13: وقائي | F13: متطوع/ة | G13: أشرف الصليبي | H13: أشرف الصليبي | I13: البرامج النسائية - النصيرات | J13: الوسطى | K13: النصيرات | L13: =COUNTIF($I$4:$I$148,I13) -> 8 | M13: سليم
A14: 11 | B14: 403688468 | C14: احمد سامي سلامه العطار | D14: 592087997 | E14: وقائي | F14: متطوع/ة | G14: أشرف الصليبي | H14: أشرف الصليبي | I14: الحكر | J14: الوسطى | K14: دير البلح | L14: =COUNTIF($I$4:$I$148,I14) -> 4 | M14: سليم
A15: 12 | B15: 407685163 | C15: اسلام سامي سلامة العطار | D15: 595782889 | E15: وقائي | F15: أمن | G15: أشرف الصليبي | H15: أشرف الصليبي | I15: الحكر | J15: الوسطى | K15: دير البلح | L15: =COUNTIF($I$4:$I$148,I15) -> 4 | M15: سليم
A16: 13 | B16: 404143521 | C16: فاطمة بسام علي أبو بشير | D16: 567092181 | E16: وقائي | F16: موظف/ة | G16: أشرف الصليبي | H16: أشرف الصليبي | I16: الحكر | J16: الوسطى | K16: دير البلح | L16: =COUNTIF($I$4:$I$148,I16) -> 4 | M16: سليم
... A37: 34 | B37: 400266433 | C37: نجاة عبدالعاطي سالم بركة | D37: 597923987 | E37: وقائي | F37: موظف/ة | G37: أشرف الصليبي | H37: أشرف الصليبي | I37: حنين | J37: خانيونس | K37: القرارة | L37: =COUNTIF($I$4:$I$148,I37) -> 5 | M37: سليم
A38: 35 | B38: 802881151 | C38: نور سمير شكري حضر | D38: 599309536 | E38: وقائي | F38: متطوع/ة | G38: أشرف الصليبي | H38: أشرف الصليبي | I38: حنين | J38: الوسطى | K38: خانيونس | L38: =COUNTIF($I$4:$I$148,I38) -> 5 | M38: سليم
A39: 36 | B39: 405138363 | C39: جيهان رامي موسى أبو خاطر | D39: 592389161 | E39: وقائي | F39: موظف/ة | G39: أشرف الصليبي | H39: أشرف الصليبي | I39: حنين | J39: خانيونس | K39: خانيونس | L39: =COUNTIF($I$4:$I$148,I39) -> 5 | M39: سليم
A40: 37 | B40: 803512144 | C40: أنس عبد المالك عبد المؤمن غانم | D40: 597093982 | E40: وقائي | F40: موظف/ة | G40: أشرف الصليبي | H40: أشرف الصليبي | I40: صفا - النصيرات | J40: الوسطى | K40: النصيرات | L40: =COUNTIF($I$4:$I$148,I40) -> 4 | M40: سليم
A41: 38 | B41: 403685738 | C41: ايمان خالد خليل عوض | D41: 592057266 | E41: وقائي | F41: موظف/ة | G41: أشرف الصليبي | H41: أشرف الصليبي | I41: صفا - النصيرات | J41: الوسطى | K41: النصيرات | L41: =COUNTIF($I$4:$I$148,I41) -> 4 | M41: سليم
A42: 39 | B42: 800510091 | C42: سامر سمير محمد ابو عريبان | D42: 597081200 | E42: وقائي | F42: أمن | G42: أشرف الصليبي | H42: أشرف الصليبي | I42: صفا - النصيرات | J42: الوسطى | K42: النصيرات | L42: =COUNTIF($I$4:$I$148,I42) -> 4 | M42: سليم
A43: 40 | B43: 407706449 | C43: حنان اسامه اسماعيل عبدالعال | D43: 595223854 | E43: وقائي | F43: متطوع/ة | G43: أشرف الصليبي | H43: أشرف الصليبي | I43: صفا - النصيرات | J43: خانيونس | K43: خانيونس | L43: =COUNTIF($I$4:$I$148,I43) -> 4 | M43: سليم
A44: 41 | B44: 404193849 | C44: ريما عبد المجيد فضل مصلح | D44: 599107778 | E44: وقائي | F44: موظف/ة | G44: براء الاسطل | H44: براء الاسطل | I44: ابو دلال | J44: الوسطى | K44: دير البلح | L44: =COUNTIF($I$4:$I$148,I44) -> 5 | M44: سليم
A45: 42 | B45: 944820992 | C45: زياد محمد حماد ابو خطاب | D45: 592890987 | E45: وقائي | F45: موظف/ة | G45: براء الاسطل | H45: براء الاسطل | I45: ابو دلال | J45: الوسطى | K45: دير البلح | L45: =COUNTIF($I$4:$I$148,I45) -> 5 | M45: سليم
A46: 43 | B46: 404599854 | C46: عبدالرحمن عبدالله محمود راضي | D46: 595124172 | E46: وقائي | F46: متطوع/ة | G46: براء الاسطل | H46: براء الاسطل | I46: ابو دلال | J46: الوسطى | K46: دير البلح | L46: =COUNTIF($I$4:$I$148,I46) -> 5 | M46: سليم
A47: 44 | B47: 408854875 | C47: محمد فراج محمد السواركة | D47: 599960444 | E47: وقائي | F47: أمن | G47: براء الاسطل | H47: براء الاسطل | I47: ابو دلال | J47: الوسطى | K47: دير البلح | L47: =COUNTIF($I$4:$I$148,I47) -> 5 | M47: سليم
A48: 45 | B48: 403809171 | C48: ميسون كمال خليل بربخ | D48: 594116358 | E48: وقائي | F48: موظف/ة | G48: براء الاسطل | H48: براء الاسطل | I48: ابو دلال | J48: الوسطى | K48: دير البلح | L48: =COUNTIF($I$4:$I$148,I48) -> 5 | M48: سليم
A49: 46 | B49: 408399376 | C49: بيسان عادل محمد أبو هويشل | D49: 592424809 | E49: علاجي | F49: متطوع/ة | G49: براء الاسطل | H49: براء الاسطل | I49: ابو معيلق | J49: الوسطى | K49: دير البلح | L49: =COUNTIF($I$4:$I$148,I49) -> 5 | M49: سليم
A50: 47 | B50: 405848177 | C50: أسيل ناصر سلمان ابو سبيخة | D50: 598293530 | E50: وقائي | F50: موظف/ة | G50: براء الاسطل | H50: براء الاسطل | I50: ابو معيلق | J50: الوسطى | K50: دير البلح | L50: =COUNTIF($I$4:$I$148,I50) -> 5 | M50: سليم
... A148: 145 | B148: 400159919 | C148: نور الهدى زياد مطلق الداهودي | D148: 597779816 | E148: وقائي | F148: موظف/ة | G148: ياسمين النجيلي | H148: ياسمين النجيلي | I148: أرض الطيبة | J148: خانيونس | K148: خانيونس | L148: =COUNTIF($I$4:$I$148,I148) -> 4 | M148: سليم
